Workbook

Sheet Business Information
B1: Forecast Assumptions | Business Information
B3: How to use this workbook
B4: This workbook contains the completed forecast assumptions and P&L from Tasks 1 and 2. Use those completed worksheets to build the Cash Flow & Debt Forecast. Link to existing cells rather than re-entering values.
B6: Revenue
B7: Product | C7: FY2026E starting units | D7: FY2026E avg. sale price | E7: Forecast rule
B8: Baked Goods | C8: 100000 | D8: 4 | E8: From FY2027E, unit growth is 10%. Reduce the growth rate by 1 percentage point each year thereafter (9%, 8%, 7%). Average sale price grows 4% per year from FY2027E.
B9: Frozen Desserts | C9: 60000 | D9: 3 | E9: From FY2027E, unit growth is 10%. Reduce the growth rate by 1 percentage point each year thereafter (9%, 8%, 7%). Average sale price grows 4% per year from FY2027E.
B10: Beverages | C10: 50000 | D10: 2.5 | E10: From FY2027E, unit growth is 10%. Reduce the growth rate by 1 percentage point each year thereafter (9%, 8%, 7%). Average sale price grows 4% per year from FY2027E.
B12: Costs
B13: Driver | C13: FY2026E starting value | D13: Unit | E13: Forecast rule
B14: COGS per Baked Good | C14: 1.5 | D14: $ per unit | E14: Increase by 2% per year from FY2027E.
B15: COGS per Frozen Dessert | C15: 0.8 | D15: $ per unit | E15: Increase by 2% per year from FY2027E.
B16: COGS per Beverage | C16: 1.1 | D16: $ per unit | E16: Increase by 2% per year from FY2027E.
B17: Staff Costs | C17: 150000 | D17: $ | E17: Increase by 5% per year from FY2027E.
B18: Occupancy Costs | C18: 60000 | D18: $ | E18: Increase by 3% per year from FY2027E.
B19: Marketing Costs | C19: 10000 | D19: $ | E19: Increase by 5% per year from FY2027E.
B20: Other Operating Costs | C20: 5000 | D20: $ | E20: Increase by 5% per year from FY2027E.
B21: Annual D&A | C21: -0.05 | D21: % of revenue | E21: Increase by 0.25 percentage points each year (for example, -5.00% becomes -4.75% in FY2027E).
B23: Cash Flow
B24: Driver | C24: Starting value | D24: Unit | E24: Forecast rule
B25: Capital Expenditure (CapEx) | C25: Linked to D&A | D25: % of revenue | E25: Set CapEx equal to the Annual D&A percentage in each forecast year.
B26: Change in Net Working Capital (NWC) | C26: -0.01 | D26: % of revenue | E26: Use -1.0% of revenue in every forecast year.
B27: Dividend Payout Ratio | C27: 0.6 | D27: % | E27: Use 60.0% in every forecast year.
B29: Other
B30: Driver | C30: Starting value | D30: Unit | E30: Forecast rule
B31: Tax Rate | C31: 0.21 | D31: % | E31: Use 21.0% in every forecast year.
B32: Debt Interest Rate | C32: 0.04 | D32: % | E32: Use 4.0% in every forecast year.
B33: Cash Interest Rate | C33: 0.01 | D33: % | E33: Use 1.0% in every forecast year.

Sheet Forecast Assumptions
B1: Forecast Assumptions
B2: This worksheet contains the completed forecast assumptions from Task 1. Use these values as inputs throughout the model and link to them rather than retyping them.
B4: Driver | C4: Unit | D4: FY2026E | E4: FY2027E | F4: FY2028E | G4: FY2029E | H4: FY2030E
B6: Revenue
B7: Baked Goods
B8: Number of Units Sold | C8: # | D8: 100000 | E8: =D8*(1+10%) -> 110000 | F8: =E8*(1+9%) -> 119900 | G8: =F8*(1+8%) -> 129492 | H8: =G8*(1+7%) -> 138556.44
B9: Average Sale Price | C9: $ | D9: 4 | E9: =D9*(1+4%) -> 4.16 | F9: =E9*(1+4%) -> 4.3264 | G9: =F9*(1+4%) -> 4.499456 | H9: =G9*(1+4%) -> 4.6794342
B10: Frozen Desserts
B11: Number of Units Sold | C11: # | D11: 60000 | E11: =D11*(1+10%) -> 66000 | F11: =E11*(1+9%) -> 71940 | G11: =F11*(1+8%) -> 77695.2 | H11: =G11*(1+7%) -> 83133.864
B12: Average Sale Price | C12: $ | D12: 3 | E12: =D12*(1+4%) -> 3.12 | F12: =E12*(1+4%) -> 3.2448 | G12: =F12*(1+4%) -> 3.374592 | H12: =G12*(1+4%) -> 3.5095757
B13: Beverages
B14: Number of Units Sold | C14: # | D14: 50000 | E14: =D14*(1+10%) -> 55000 | F14: =E14*(1+9%) -> 59950 | G14: =F14*(1+8%) -> 64746 | H14: =G14*(1+7%) -> 69278.22
B15: Average Sale Price | C15: $ | D15: 2.5 | E15: =D15*(1+4%) -> 2.6 | F15: =E15*(1+4%) -> 2.704 | G15: =F15*(1+4%) -> 2.81216 | H15: =G15*(1+4%) -> 2.9246464
B17: Costs
B18: Cost of Goods Sold (COGS)
B19: COGS per Baked Good | C19: $ per unit | D19: 1.5 | E19: =D19*(1+0.02) -> 1.53 | F19: =E19*(1+0.02) -> 1.5606 | G19: =F19*(1+0.02) -> 1.591812 | H19: =G19*(1+0.02) -> 1.6236482
B20: COGS per Frozen Dessert | C20: $ per unit | D20: 0.8 | E20: =D20*(1+0.02) -> 0.816 | F20: =E20*(1+0.02) -> 0.83232 | G20: =F20*(1+0.02) -> 0.8489664 | H20: =G20*(1+0.02) -> 0.86594573
B21: COGS per Beverage | C21: $ per unit | D21: 1.1 | E21: =D21*(1+0.02) -> 1.122 | F21: =E21*(1+0.02) -> 1.14444 | G21: =F21*(1+0.02) -> 1.1673288 | H21: =G21*(1+0.02) -> 1.1906754
B22: Operating Expenses (OpEx)
B23: Staff Costs | C23: $ | D23: 150000 | E23: =D23*(1+0.05) -> 157500 | F23: =E23*(1+0.05) -> 165375 | G23: =F23*(1+0.05) -> 173643.75 | H23: =G23*(1+0.05) -> 182325.94
B24: Occupancy Costs | C24: $ | D24: 60000 | E24: =D24*(1+0.03) -> 61800 | F24: =E24*(1+0.03) -> 63654 | G24: =F24*(1+0.03) -> 65563.62 | H24: =G24*(1+0.03) -> 67530.529
B25: Marketing Costs | C25: $ | D25: 10000 | E25: =D25*(1+0.05) -> 10500 | F25: =E25*(1+0.05) -> 11025 | G25: =F25*(1+0.05) -> 11576.25 | H25: =G25*(1+0.05) -> 12155.062
B26: Other Operating Costs | C26: $ | D26: 5000 | E26: =D26*(1+0.05) -> 5250 | F26: =E26*(1+0.05) -> 5512.5 | G26: =F26*(1+0.05) -> 5788.125 | H26: =G26*(1+0.05) -> 6077.5312
B27: Depreciation & Amortization (D&A)
B28: Annual D&A | C28: % of revenue | D28: -0.05 | E28: =D28+0.0025 -> -0.0475 | F28: =E28+0.0025 -> -0.045 | G28: =F28+0.0025 -> -0.0425 | H28: =G28+0.0025 -> -0.04
B30: Cash Flow
B31: Capital Expenditure (CapEx) | C31: % of revenue | D31: =D28 -> -0.05 | E31: =E28 -> -0.0475 | F31: =F28 -> -0.045 | G31: =G28 -> -0.0425 | H31: =H28 -> -0.04
B32: Change in Net Working Capital (NWC) | C32: % of revenue | D32: -0.01 | E32: -0.01 | F32: -0.01 | G32: -0.01 | H32: -0.01
B33: Dividend Payout Ratio | C33: % | D33: 0.6 | E33: 0.6 | F33: 0.6 | G33: 0.6 | H33: 0.6
B35: Other
B36: Tax Rate | C36: % | D36: 0.21 | E36: 0.21 | F36: 0.21 | G36: 0.21 | H36: 0.21
B37: Debt Interest Rate | C37: % | D37: 0.04 | E37: 0.04 | F37: 0.04 | G37: 0.04 | H37: 0.04
B38: Cash Interest Rate | C38: % | D38: 0.01 | E38: 0.01 | F38: 0.01 | G38: 0.01 | H38: 0.01
B40: Tip: Check that percentages, dollar values, and unit counts use the correct number format before submitting your workbook.

Sheet P&L Forecast
B1: P&L Forecast
B2: This worksheet contains the completed P&L from Task 2. After calculating Net Interest Expense in Task 3, replace the temporary interest values in row 36 with links to the Cash Flow & Debt Forecast.
B4: P&L Line | C4: Unit | D4: FY2026E | E4: FY2027E | F4: FY2028E | G4: FY2029E | H4: FY2030E
B6: Revenue
B7: Baked Goods Revenue | C7: $ | D7: ='Forecast Assumptions'!D8*'Forecast Assumptions'!D9 -> 400000 | E7: ='Forecast Assumptions'!E8*'Forecast Assumptions'!E9 -> 457600 | F7: ='Forecast Assumptions'!F8*'Forecast Assumptions'!F9 -> 518735.36 | G7: ='Forecast Assumptions'!G8*'Forecast Assumptions'!G9 -> 582643.56 | H7: ='Forecast Assumptions'!H8*'Forecast Assumptions'!H9 -> 648365.75
B8: Frozen Desserts Revenue | C8: $ | D8: ='Forecast Assumptions'!D11*'Forecast Assumptions'!D12 -> 180000 | E8: ='Forecast Assumptions'!E11*'Forecast Assumptions'!E12 -> 205920 | F8: ='Forecast Assumptions'!F11*'Forecast Assumptions'!F12 -> 233430.91 | G8: ='Forecast Assumptions'!G11*'Forecast Assumptions'!G12 -> 262189.6 | H8: ='Forecast Assumptions'!H11*'Forecast Assumptions'!H12 -> 291764.59
B9: Beverages Revenue | C9: $ | D9: ='Forecast Assumptions'!D14*'Forecast Assumptions'!D15 -> 125000 | E9: ='Forecast Assumptions'!E14*'Forecast Assumptions'!E15 -> 143000 | F9: ='Forecast Assumptions'!F14*'Forecast Assumptions'!F15 -> 162104.8 | G9: ='Forecast Assumptions'!G14*'Forecast Assumptions'!G15 -> 182076.11 | H9: ='Forecast Assumptions'!H14*'Forecast Assumptions'!H15 -> 202614.3
B10: Total Revenue | C10: $ | D10: =SUM(D7:D9) -> 705000 | E10: =SUM(E7:E9) -> 806520 | F10: =SUM(F7:F9) -> 914271.07 | G10: =SUM(G7:G9) -> 1026909.3 | H10: =SUM(H7:H9) -> 1142744.6
B11: Revenue Growth | C11: % | D11: — | E11: =E10/D10-1 -> 0.144 | F11: =F10/E10-1 -> 0.1336 | G11: =G10/F10-1 -> 0.1232 | H11: =H10/G10-1 -> 0.1128
B13: Cost of Goods Sold
B14: Baked Goods COGS | C14: $ | D14: ='Forecast Assumptions'!D8*'Forecast Assumptions'!D19 -> 150000 | E14: ='Forecast Assumptions'!E8*'Forecast Assumptions'!E19 -> 168300 | F14: ='Forecast Assumptions'!F8*'Forecast Assumptions'!F19 -> 187115.94 | G14: ='Forecast Assumptions'!G8*'Forecast Assumptions'!G19 -> 206126.92 | H14: ='Forecast Assumptions'!H8*'Forecast Assumptions'!H19 -> 224966.92
B15: Frozen Desserts COGS | C15: $ | D15: ='Forecast Assumptions'!D11*'Forecast Assumptions'!D20 -> 48000 | E15: ='Forecast Assumptions'!E11*'Forecast Assumptions'!E20 -> 53856 | F15: ='Forecast Assumptions'!F11*'Forecast Assumptions'!F20 -> 59877.101 | G15: ='Forecast Assumptions'!G11*'Forecast Assumptions'!G20 -> 65960.614 | H15: ='Forecast Assumptions'!H11*'Forecast Assumptions'!H20 -> 71989.414
B16: Beverages COGS | C16: $ | D16: ='Forecast Assumptions'!D14*'Forecast Assumptions'!D21 -> 55000 | E16: ='Forecast Assumptions'!E14*'Forecast Assumptions'!E21 -> 61710 | F16: ='Forecast Assumptions'!F14*'Forecast Assumptions'!F21 -> 68609.178 | G16: ='Forecast Assumptions'!G14*'Forecast Assumptions'!G21 -> 75579.87 | H16: ='Forecast Assumptions'!H14*'Forecast Assumptions'!H21 -> 82487.871
B17: Total Cost of Goods Sold | C17: $ | D17: =SUM(D14:D16) -> 253000 | E17: =SUM(E14:E16) -> 283866 | F17: =SUM(F14:F16) -> 315602.22 | G17: =SUM(G14:G16) -> 347667.4 | H17: =SUM(H14:H16) -> 379444.2
B19: Gross Profit | C19: $ | D19: =D10-D17 -> 452000 | E19: =E10-E17 -> 522654 | F19: =F10-F17 -> 598668.85 | G19: =G10-G17 -> 679241.86 | H19: =H10-H17 -> 763300.43
B20: Gross Margin | C20: % | D20: =D19/D10 -> 0.64113475 | E20: =E19/E10 -> 0.64803601 | F20: =F19/F10 -> 0.65480454 | G20: =G19/G10 -> 0.66144292 | H20: =H19/H10 -> 0.66795363
B22: Operating Expenses
B23: Staff Costs | C23: $ | D23: ='Forecast Assumptions'!D23 -> 150000 | E23: ='Forecast Assumptions'!E23 -> 157500 | F23: ='Forecast Assumptions'!F23 -> 165375 | G23: ='Forecast Assumptions'!G23 -> 173643.75 | H23: ='Forecast Assumptions'!H23 -> 182325.94
B24: Occupancy Costs | C24: $ | D24: ='Forecast Assumptions'!D24 -> 60000 | E24: ='Forecast Assumptions'!E24 -> 61800 | F24: ='Forecast Assumptions'!F24 -> 63654 | G24: ='Forecast Assumptions'!G24 -> 65563.62 | H24: ='Forecast Assumptions'!H24 -> 67530.529
B25: Marketing Costs | C25: $ | D25: ='Forecast Assumptions'!D25 -> 10000 | E25: ='Forecast Assumptions'!E25 -> 10500 | F25: ='Forecast Assumptions'!F25 -> 11025 | G25: ='Forecast Assumptions'!G25 -> 11576.25 | H25: ='Forecast Assumptions'!H25 -> 12155.062
B26: Other Operating Costs | C26: $ | D26: ='Forecast Assumptions'!D26 -> 5000 | E26: ='Forecast Assumptions'!E26 -> 5250 | F26: ='Forecast Assumptions'!F26 -> 5512.5 | G26: ='Forecast Assumptions'!G26 -> 5788.125 | H26: ='Forecast Assumptions'!H26 -> 6077.5312
B27: Total Operating Expenses | C27: $ | D27: =SUM(D23:D26) -> 225000 | E27: =SUM(E23:E26) -> 235050 | F27: =SUM(F23:F26) -> 245566.5 | G27: =SUM(G23:G26) -> 256571.74 | H27: =SUM(H23:H26) -> 268089.06
B29: EBITDA | C29: $ | D29: =D19-D27 -> 227000 | E29: =E19-E27 -> 287604 | F29: =F19-F27 -> 353102.35 | G29: =G19-G27 -> 422670.12 | H29: =H19-H27 -> 495211.37
B30: EBITDA Margin | C30: % | D30: =D29/D10 -> 0.32198582 | E30: =E29/E10 -> 0.35659872 | F30: =F29/F10 -> 0.38621188 | G30: =G29/G10 -> 0.41159441 | H30: =H29/H10 -> 0.43335261
B32: Profit After D&A, Interest and Tax
B33: Depreciation & Amortization | C33: $ | D33: =-D10*'Forecast Assumptions'!D28 -> 35250 | E33: =-E10*'Forecast Assumptions'!E28 -> 38309.7 | F33: =-F10*'Forecast Assumptions'!F28 -> 41142.198 | G33: =-G10*'Forecast Assumptions'!G28 -> 43643.644 | H33: =-H10*'Forecast Assumptions'!H28 -> 45709.785
B34: EBIT | C34: $ | D34: =D29-D33 -> 191750 | E34: =E29-E33 -> 249294.3 | F34: =F29-F33 -> 311960.15 | G34: =G29-G33 -> 379026.47 | H34: =H29-H33 -> 449501.58
B36: Net Interest Expense | C36: $ | D36: ='Cash Flow & Debt Forecast'!D40 -> 15850 | E36: ='Cash Flow & Debt Forecast'!E40 -> 13908.624 | F36: ='Cash Flow & Debt Forecast'!F40 -> 11255.957 | G36: ='Cash Flow & Debt Forecast'!G40 -> 7820.7644 | H36: ='Cash Flow & Debt Forecast'!H40 -> 3539.4879
B37: Profit Before Tax | C37: $ | D37: =D34-D36 -> 175900 | E37: =E34-E36 -> 235385.68 | F37: =F34-F36 -> 300704.2 | G37: =G34-G36 -> 371205.71 | H37: =H34-H36 -> 445962.1
B38: Tax Expense | C38: $ | D38: =D37*'Forecast Assumptions'!D36 -> 36939 | E38: =E37*'Forecast Assumptions'!E36 -> 49430.992 | F38: =F37*'Forecast Assumptions'!F36 -> 63147.882 | G38: =G37*'Forecast Assumptions'!G36 -> 77953.199 | H38: =H37*'Forecast Assumptions'!H36 -> 93652.04
B39: Net Profit | C39: $ | D39: =D37-D38 -> 138961 | E39: =E37-E38 -> 185954.68 | F39: =F37-F38 -> 237556.32 | G39: =G37-G38 -> 293252.51 | H39: =H37-H38 -> 352310.06
B42: Net Interest Expense is now linked to the completed Cash Flow & Debt Forecast. Profit Before Tax, Tax Expense, and Net Profit update automatically from the connected interest calculations.
B44: Modeling key
B45: Light-blue cells | C45: Complete these cells.
B46: Green text | C46: Use a formula that links to another worksheet.
B47: Black text | C47: Use a formula calculated within the P&L.
B48: Green text / linked values | C48: Linked to another worksheet in the completed model.
B50: Tip: Link assumptions rather than retyping them. Check that your formulas extend across all five forecast years. In this P&L, expense lines are shown as positive amounts and subtracted when calculating profit subtotals.

Sheet Cash Flow & Debt Forecast
B1: Cash Flow & Debt Forecast
B2: Complete every light blue cell. Link to the completed P&L and Forecast Assumptions, then build the cash, debt, and interest calculations across FY2026E–FY2030E.
B4: Cash Flow / Debt Line | C4: Unit | D4: FY2026E | E4: FY2027E | F4: FY2028E | G4: FY2029E | H4: FY2030E
B6: Operating Cash Flow
B7: Net Profit | C7: $ | D7: ='P&L Forecast'!D39 -> 138961 | E7: ='P&L Forecast'!E39 -> 185954.68 | F7: ='P&L Forecast'!F39 -> 237556.32 | G7: ='P&L Forecast'!G39 -> 293252.51 | H7: ='P&L Forecast'!H39 -> 352310.06
B8: Depreciation & Amortization | C8: $ | D8: ='P&L Forecast'!D33 -> 35250 | E8: ='P&L Forecast'!E33 -> 38309.7 | F8: ='P&L Forecast'!F33 -> 41142.198 | G8: ='P&L Forecast'!G33 -> 43643.644 | H8: ='P&L Forecast'!H33 -> 45709.785
B9: Change in Net Working Capital | C9: $ | D9: ='Forecast Assumptions'!D32*'P&L Forecast'!D10 -> -7050 | E9: ='Forecast Assumptions'!E32*'P&L Forecast'!E10 -> -8065.2 | F9: ='Forecast Assumptions'!F32*'P&L Forecast'!F10 -> -9142.7107 | G9: ='Forecast Assumptions'!G32*'P&L Forecast'!G10 -> -10269.093 | H9: ='Forecast Assumptions'!H32*'P&L Forecast'!H10 -> -11427.446
B10: Operating Cash Flow | C10: $ | D10: =SUM(D7:D9) -> 167161 | E10: =SUM(E7:E9) -> 216199.18 | F10: =SUM(F7:F9) -> 269555.8 | G10: =SUM(G7:G9) -> 326627.06 | H10: =SUM(H7:H9) -> 386592.39
B12: Investing Cash Flow
B13: Capital Expenditure | C13: $ | D13: ='Forecast Assumptions'!D31*'P&L Forecast'!D10 -> -35250 | E13: ='Forecast Assumptions'!E31*'P&L Forecast'!E10 -> -38309.7 | F13: ='Forecast Assumptions'!F31*'P&L Forecast'!F10 -> -41142.198 | G13: ='Forecast Assumptions'!G31*'P&L Forecast'!G10 -> -43643.644 | H13: ='Forecast Assumptions'!H31*'P&L Forecast'!H10 -> -45709.785
B14: Investing Cash Flow | C14: $ | D14: =D13 -> -35250 | E14: =E13 -> -38309.7 | F14: =F13 -> -41142.198 | G14: =G13 -> -43643.644 | H14: =H13 -> -45709.785
B16: Financing Cash Flow
B17: Dividends | C17: $ | D17: =-'Forecast Assumptions'!D33*'P&L Forecast'!D39 -> -83376.6 | E17: =-'Forecast Assumptions'!E33*'P&L Forecast'!E39 -> -111572.81 | F17: =-'Forecast Assumptions'!F33*'P&L Forecast'!F39 -> -142533.79 | G17: =-'Forecast Assumptions'!G33*'P&L Forecast'!G39 -> -175951.51 | H17: =-'Forecast Assumptions'!H33*'P&L Forecast'!H39 -> -211386.03
B18: Cash Flow Before Debt | C18: $ | D18: =D10+D14+D17 -> 48534.4 | E18: =E10+E14+E17 -> 66316.674 | F18: =F10+F14+F17 -> 85879.816 | G18: =G10+G14+G17 -> 107031.91 | H18: =H10+H14+H17 -> 129496.58
B19: Debt Issued | C19: $ | D19: 0 | E19: 0 | F19: 0 | G19: 0 | H19: 0
B20: Debt Repayment | C20: $ | D20: =D32 -> -48534.4 | E20: =E32 -> -66316.674 | F20: =F32 -> -85879.816 | G20: =G32 -> -107031.91 | H20: =H32 -> -92237.199
B21: Financing Cash Flow | C21: $ | D21: =D17+D19+D20 -> -131911 | E21: =E17+E19+E20 -> -177889.48 | F21: =F17+F19+F20 -> -228413.61 | G21: =G17+G19+G20 -> -282983.42 | H21: =H17+H19+H20 -> -303623.23
B22: Net Cash Flow | C22: $ | D22: =D10+D14+D21 -> 0 | E22: =E10+E14+E21 -> 0 | F22: =F10+F14+F21 -> 0 | G22: =G10+G14+G21 -> 0 | H22: =H10+H14+H21 -> 37259.377
B24: Cash Schedule
B25: Opening Cash | C25: $ | D25: 15000 | E25: =D27 -> 15000 | F25: =E27 -> 15000 | G25: =F27 -> 15000 | H25: =G27 -> 15000
B26: Net Cash Flow | C26: $ | D26: =D22 -> 0 | E26: =E22 -> 0 | F26: =F22 -> 0 | G26: =G22 -> 0 | H26: =H22 -> 37259.377
B27: Closing Cash | C27: $ | D27: =D25+D26 -> 15000 | E27: =E25+E26 -> 15000 | F27: =F25+F26 -> 15000 | G27: =G25+G26 -> 15000 | H27: =H25+H26 -> 52259.377
B29: Supporting Debt Schedule
B30: Opening Debt | C30: $ | D30: 400000 | E30: =D33 -> 351465.6 | F30: =E33 -> 285148.93 | G30: =F33 -> 199269.11 | H30: =G33 -> 92237.199
B31: Debt Issued | C31: $ | D31: =D19 -> 0 | E31: =E19 -> 0 | F31: =F19 -> 0 | G31: =G19 -> 0 | H31: =H19 -> 0
B32: Debt Repayment | C32: $ | D32: =-MIN(MAX(D18,0),D30) -> -48534.4 | E32: =-MIN(MAX(E18,0),E30) -> -66316.674 | F32: =-MIN(MAX(F18,0),F30) -> -85879.816 | G32: =-MIN(MAX(G18,0),G30) -> -107031.91 | H32: =-MIN(MAX(H18,0),H30) -> -92237.199
B33: Closing Debt | C33: $ | D33: =D30+D31+D32 -> 351465.6 | E33: =E30+E31+E32 -> 285148.93 | F33: =F30+F31+F32 -> 199269.11 | G33: =G30+G31+G32 -> 92237.199 | H33: =H30+H31+H32 -> 0
B35: Interest Calculations
B36: Debt Interest Rate | C36: % | D36: ='Forecast Assumptions'!D37 -> 0.04 | E36: ='Forecast Assumptions'!E37 -> 0.04 | F36: ='Forecast Assumptions'!F37 -> 0.04 | G36: ='Forecast Assumptions'!G37 -> 0.04 | H36: ='Forecast Assumptions'!H37 -> 0.04
B37: Interest Expense | C37: $ | D37: =D30*D36 -> 16000 | E37: =E30*E36 -> 14058.624 | F37: =F30*F36 -> 11405.957 | G37: =G30*G36 -> 7970.7644 | H37: =H30*H36 -> 3689.4879
B38: Cash Interest Rate | C38: % | D38: ='Forecast Assumptions'!D38 -> 0.01 | E38: ='Forecast Assumptions'!E38 -> 0.01 | F38: ='Forecast Assumptions'!F38 -> 0.01 | G38: ='Forecast Assumptions'!G38 -> 0.01 | H38: ='Forecast Assumptions'!H38 -> 0.01
B39: Interest Income | C39: $ | D39: =D25*D38 -> 150 | E39: =E25*E38 -> 150 | F39: =F25*F38 -> 150 | G39: =G25*G38 -> 150 | H39: =H25*H38 -> 150
B40: Net Interest Expense | C40: $ | D40: =D37-D39 -> 15850 | E40: =E37-E39 -> 13908.624 | F40: =F37-F39 -> 11255.957 | G40: =G37-G39 -> 7820.7644 | H40: =H37-H39 -> 3539.4879
B43: Modeling Instructions
B44: Start with the completed P&L and Forecast Assumptions. Link existing values instead of re-entering them.
B45: FY2026E Opening Cash ($15,000) and Opening Debt ($400,000) are provided. Roll each closing balance into the next year's opening balance.
B46: Assume no new debt is issued. Use positive Cash Flow Before Debt to repay debt, up to the amount of Opening Debt. Once debt is repaid, excess cash remains as Closing Cash.
B47: Calculate interest using Opening Debt and Opening Cash for each year. Net Interest Expense = Interest Expense - Interest Income.
B48: After completing Net Interest Expense, replace the Temporary Net Interest Expense values on the P&L with links to this worksheet and confirm the model updates correctly.
B50: Modeling key
...

Sheet Glossary
B1: Financial Modeling Glossary
B3: Term | C3: Definition
B4: Capital Expenditure (CapEx) | C4: Spending on long-term assets such as equipment, property, or technology that supports the business over multiple periods.
B5: Cost of Goods Sold (COGS) | C5: The direct costs associated with producing the goods or services sold by a business.
B6: Depreciation & Amortization (D&A) | C6: Non-cash expenses that allocate the cost of tangible and intangible assets over their useful lives.
B7: Dividend Payout Ratio | C7: The percentage of net profit distributed to shareholders as dividends.
B8: EBITDA | C8: Earnings before interest, taxes, depreciation, and amortization. It is commonly used as a measure of operating profitability before financing, tax, and non-cash D&A expenses.
B9: EBIT | C9: Earnings before interest and taxes. It represents operating profit after depreciation and amortization.
B10: Net Working Capital (NWC) | C10: A measure of short-term operating assets and liabilities. Changes in NWC can either use or release cash.
B11: Operating Expenses (OpEx) | C11: Ongoing costs of running the business that are not direct product costs, such as staff, occupancy, marketing, and administrative costs.
B12: Profit & Loss Statement (P&L) | C12: A financial statement that summarizes revenue, expenses, and profit or loss over a period of time.
B13: Working Capital | C13: The short-term resources needed to support day-to-day operations, including items such as receivables, inventory, and payables.
B14: Cash Flow Forecast | C14: A forecast showing how cash is generated and used across operating, investing, and financing activities over time.
... B20: Closing Cash | C20: The cash balance at the end of a forecast period after adding Net Cash Flow to Opening Cash.
